<?xml version="1.0" ?>
<robot name="denso_vp6242" xmlns:xacro="http://www.ros.org/wiki/xacro">
<xacro:property name="scale_value" value="100.0"/>
  
  <link name="world"/>
	<joint name="joint_w" type="fixed">
		<parent link="world"/>
		<child link="base_link"/>
	</joint>

   <link name="base_link">
    <visual>
      <geometry>
        <mesh filename="package://denso_vp6242_description/meshes/visual/base.dae" scale="${scale_value * 0.001} ${scale_value * 0.001} ${scale_value * 0.001}"/>
      </geometry>
      <origin rpy="-1.570796 3.141592 0" xyz="0 0 0"/>
    </visual>
    <collision>
      <geometry>
        <mesh filename="package://denso_vp6242_description/meshes/collision/base.dae" scale="${scale_value * 0.001} ${scale_value * 0.001} ${scale_value * 0.001}"/>
      </geometry>
      <origin rpy="-1.570796 3.141592 0" xyz="0 0 0"/>
    </collision>
  </link>
  <link name="link1">
    <visual>
      <geometry>
        <mesh filename="package://denso_vp6242_description/meshes/visual/link1.dae" scale="${scale_value * 0.001} ${scale_value * 0.001} ${scale_value * 0.001}"/>
      </geometry>
      <origin rpy="-1.570796 3.141592 0" xyz="0 0 0"/>
    </visual>
    <collision>
      <geometry>
        <mesh filename="package://denso_vp6242_description/meshes/collision/link1.dae" scale="${scale_value * 0.001} ${scale_value * 0.001} ${scale_value * 0.001}"/>
      </geometry>
      <origin rpy="-1.570796 3.141592 0" xyz="0 0 0"/>
    </collision>
  </link>
  <link name="link2">
    <visual>
      <geometry>
        <mesh filename="package://denso_vp6242_description/meshes/visual/link2.dae" scale="${scale_value * 0.001} ${scale_value * 0.001} ${scale_value * 0.001}"/>
      </geometry>
      <origin rpy="-1.570796 3.141592 0" xyz="0 0 0"/>
    </visual>
    <collision>
      <geometry>
        <mesh filename="package://denso_vp6242_description/meshes/collision/link2.dae" scale="${scale_value * 0.001} ${scale_value * 0.001} ${scale_value * 0.001}"/>
      </geometry>
      <origin rpy="-1.570796 3.141592 0" xyz="0 0 0"/>
    </collision>
  </link>
  <link name="link3">
    <visual>
      <geometry>
        <mesh filename="package://denso_vp6242_description/meshes/visual/link3.dae" scale="${scale_value * 0.001} ${scale_value * 0.001} ${scale_value * 0.001}"/>
      </geometry>
      <origin rpy="-1.570796 1.570796 0" xyz="0 0 0"/>
    </visual>
    <collision>
      <geometry>
        <mesh filename="package://denso_vp6242_description/meshes/collision/link3.dae" scale="${scale_value * 0.001} ${scale_value * 0.001} ${scale_value * 0.001}"/>
      </geometry>
      <origin rpy="-1.570796 1.570796 0" xyz="0 0 0"/>
    </collision>
  </link>
  <link name="link4">
    <visual>
      <geometry>
        <mesh filename="package://denso_vp6242_description/meshes/visual/link4.dae" scale="${scale_value * 0.001} ${scale_value * 0.001} ${scale_value * 0.001}"/>
      </geometry>
      <origin rpy="0 1.570796 1.570796" xyz="0 0 ${scale_value*0.085}"/>
    </visual>
    <collision>
      <geometry>
        <mesh filename="package://denso_vp6242_description/meshes/collision/link4.dae" scale="${scale_value * 0.001} ${scale_value * 0.001} ${scale_value * 0.001}"/>
      </geometry>
      <origin rpy="0 1.570796 1.570796" xyz="0 0 ${scale_value*0.085}"/>
    </collision>
  </link>
  <link name="link5">
    <visual>
      <geometry>
        <mesh filename="package://denso_vp6242_description/meshes/visual/link5.dae" scale="${scale_value * 0.001} ${scale_value * 0.001} ${scale_value * 0.001}"/>
      </geometry>
      <origin rpy="0 1.570796 1.570796" xyz="0 0 0.0"/>
    </visual>
    <collision>
      <geometry>
        <mesh filename="package://denso_vp6242_description/meshes/collision/link5.dae" scale="${scale_value * 0.001} ${scale_value * 0.001} ${scale_value * 0.001}"/>
      </geometry>
      <origin rpy="0 1.570796 1.570796" xyz="0 0 0.0"/>
    </collision>
  </link>
  <link name="link6">
    <visual>
      <geometry>
        <cylinder length="${scale_value*0.01}" radius="${scale_value*0.0205}"/>
      </geometry>
      <origin rpy="0 0 0" xyz="0.0 0.0 ${-scale_value*0.005}"/>
      <material name="plate">
        <color rgba="0.1 0.1 0.1 0.8"/>
      </material>
    </visual>
    <collision>
      <geometry>
        <cylinder length="${scale_value*0.01}" radius="${scale_value*0.0205}"/>
      </geometry>
      <origin rpy="0 0 0" xyz="0.0 0.0 ${-scale_value*0.005}"/>
    </collision>
  </link>
  <link name="tool0"/>
  <!-- Joint list -->
  <joint name="joint1" type="revolute">
    <origin rpy="0 0 0" xyz="0.0 0.0 ${scale_value*0.155}"/>
    <parent link="base_link"/>
    <child link="link1"/>
    <axis xyz="0 0 1"/>
    <limit effort="100000" lower="-2.792526803" upper="2.792526803" velocity="4.36332312999"/>
  </joint>
  <joint name="joint2" type="revolute">
    <origin rpy="0 0 0" xyz="0.0 0.0 ${scale_value*0.125}"/>
    <parent link="link1"/>
    <child link="link2"/>
    <axis xyz="0 1 0"/>
    <limit effort="100000" lower="-2.094395102" upper="2.094395102" velocity="3.26376570123"/>
  </joint>
  <joint name="joint3" type="revolute">
    <origin rpy="0 0 0" xyz="0.0 0.0 ${scale_value*0.210}"/>
    <parent link="link2"/>
    <child link="link3"/>
    <axis xyz="0 1 0"/>
    <limit effort="100000" lower="0.331612558" upper="2.792526803" velocity="4.36332312999"/>
  </joint>
  <joint name="joint4" type="revolute">
    <origin rpy="0 0 0" xyz="${-scale_value*0.075} 0.0 0.0"/>
    <parent link="link3"/>
    <child link="link4"/>
    <axis xyz="0 0 1"/>
    <limit effort="100000" lower="-2.792526803" upper="2.792526803" velocity="5.23598775598"/>
  </joint>
  <joint name="joint5" type="revolute">
    <origin rpy="0 0 0" xyz="0.0 0.0 ${scale_value*0.210}"/>
    <parent link="link4"/>
    <child link="link5"/>
    <axis xyz="0 1 0"/>
    <limit effort="100000" lower="-2.094395102" upper="2.094395102" velocity="5.23598775598"/>
  </joint>
  <joint name="joint6" type="revolute">
    <origin rpy="0 0 0" xyz="0.0 0.0 ${scale_value*0.07}"/>
    <parent link="link5"/>
    <child link="link6"/>
    <axis xyz="0 0 1"/>
    <limit effort="100000" lower="-3.14159265359" upper="3.14159265359" velocity="5.23598775598"/>
  </joint>
  <joint name="joint6-tool0" type="fixed">
    <parent link="link6"/>
    <child link="tool0"/>
    <origin rpy="0 0 0" xyz="0 0 0"/>
  </joint>
  <link name="robot_gripper_interface1">
    <collision>
      <origin rpy="0 0 0" xyz="0 0 ${scale_value*0.0045}"/>
      <geometry>
        <cylinder length="${scale_value*0.009}" radius="${scale_value*0.04}"/>
      </geometry>
    </collision>
    <visual>
      <origin rpy="0 0 0" xyz="0 0 ${scale_value*0.0045}"/>
      <geometry>
        <cylinder length="${scale_value*0.009}" radius="${scale_value*0.04}"/>
      </geometry>
      <material name="material_color_robot_gripper_interface1">
        <color rgba="0.6 1 0.6 1"/>
      </material>
    </visual>
  </link>
  <link name="robot_gripper_interface2">
    <collision>
      <origin rpy="0 0 0" xyz="0 0 ${scale_value*0.0045}"/>
      <geometry>
        <cylinder length="${scale_value*0.009}" radius="${scale_value*0.04}"/>
      </geometry>
    </collision>
    <visual>
      <origin rpy="0 0 0" xyz="0 0 ${scale_value*0.0045}"/>
      <geometry>
        <cylinder length="${scale_value*0.009}" radius="${scale_value*0.04}"/>
      </geometry>
      <material name="material_color_robot_gripper_interface2">
        <color rgba="0.6 1 0.6 1"/>
      </material>
    </visual>
  </link>
  <link name="gripper_body">
    <collision>
      <origin rpy="0 0 0" xyz="0 0 ${scale_value*0.042}"/>
      <geometry>
        <box size="${scale_value*0.11} ${scale_value*0.04} ${scale_value*0.084}"/>
      </geometry>
    </collision>
    <visual>
      <origin rpy="0 0 0" xyz="0 0 ${scale_value*0.042}"/>
      <geometry>
        <box size="${scale_value*0.11} ${scale_value*0.04} ${scale_value*0.084}"/>
      </geometry>
      <material name="material_color_gripper_body">
        <color rgba="0.2 0.2 0.2 1"/>
      </material>
    </visual>
  </link>
  <link name="right_claw">
    <collision>
      <origin rpy="0 0 0" xyz="0 0 ${scale_value*0.0068}"/>
      <geometry>
        <box size="${scale_value*0.05075} ${scale_value*0.015} ${scale_value*0.0136}"/>
      </geometry>
    </collision>
    <visual>
      <origin rpy="0 0 0" xyz="0 0 ${scale_value*0.0068}"/>
      <geometry>
        <box size="${scale_value*0.05075} ${scale_value*0.015} ${scale_value*0.0136}"/>
      </geometry>
      <material name="material_color_right_claw">
        <color rgba="0.6 0.6 1 1"/>
      </material>
    </visual>
  </link>
  <link name="left_claw">
    <collision>
      <origin rpy="0 0 0" xyz="0 0 ${scale_value*0.0068}"/>
      <geometry>
        <box size="${scale_value*0.05075} ${scale_value*0.015} ${scale_value*0.0136}"/>
      </geometry>
    </collision>
    <visual>
      <origin rpy="0 0 0" xyz="0 0 ${scale_value*0.0068}"/>
      <geometry>
        <box size="${scale_value*0.05075} ${scale_value*0.015} ${scale_value*0.0136}"/>
      </geometry>
      <material name="material_color_left_claw">
        <color rgba="0.6 0.6 1 1"/>
      </material>
    </visual>
  </link>
  <link name="peak_tool"/>
  <!--joint of robot and gripper interface-->
  <joint name="robot_to_gripper" type="fixed">
    <parent link="tool0"/>
    <child link="robot_gripper_interface1"/>
    <origin rpy="0 0 1.57079632679" xyz="0 0 0"/>
  </joint>
  <!--joint of gripper interface and body-->
  <joint name="robot_to_gripper_interface_2" type="fixed">
    <parent link="robot_gripper_interface1"/>
    <child link="robot_gripper_interface2"/>
    <origin rpy="0 0 0" xyz="0 0 ${scale_value*0.009}"/>
  </joint>
  <joint name="interface_to_gripper_body" type="fixed">
    <parent link="robot_gripper_interface2"/>
    <child link="gripper_body"/>
    <origin rpy="0 0 0" xyz="0.0 0.0 ${scale_value*0.009}"/>
  </joint>
  <!--joint of gripper and claw-->
  <joint name="right_claw_joint" type="fixed">
    <parent link="gripper_body"/>
    <child link="right_claw"/>
    <origin rpy="0 0 0" xyz="${scale_value*0.029625} 0 ${scale_value*0.084}"/>
  </joint>
  <joint name="left_claw_joint" type="fixed">
    <parent link="gripper_body"/>
    <child link="left_claw"/>
    <origin rpy="0 0 0" xyz="${-scale_value*0.029625} 0 ${scale_value*0.084}"/>
  </joint>
  <!--joint of gripper and peak tool-->
  <joint name="peak_tool" type="fixed">
    <origin rpy="0 3.14159265359 0" xyz="0 0 ${scale_value*0.0976}"/>
    <parent link="gripper_body"/>
    <child link="peak_tool"/>
  </joint>
</robot>

